Workbook

Sheet Guide
A1: BI RDG tone — hand-labelling sheet
A2: What to do | B2: Go to the 'Label' sheet. For every row, read the text and fill in the YELLOW cells: Label, Confidence, Forward-looking and (optionally) Notes. Nothing else needs editing.
A3: The question | B3: Read as a bond trader would: does this paragraph point BI toward HIGHER rates / tighter policy (Hawkish), toward LOWER rates / easier policy (Dovish), or neither (Neutral)?
A4: Blind by design | B4: Dates and decisions are hidden on purpose. Judge only the text in front of you; don't try to guess the year or look up the meeting.
A6: Labels
A7: Hawkish | B7: Signals upward pressure on rates: inflation rising or above target, rupiah depreciating or under pressure, overheating demand/credit, capital outflows, BI 'vigilant' (waspada) about risks, stance described as ketat / pre-emptive / ahead of the curve.
A8: Dovish | B8: Signals room for lower rates: inflation low or falling within target, rupiah stable or strengthening, growth weak or slowing, credit sluggish, stance described as longgar / akomodatif / mendorong pertumbuhan, explicit 'ruang penurunan' (room to cut).
A9: Neutral | B9: Descriptive with no stance implication, balanced (risks both ways), or not about monetary conditions at all.
A11: Topic matters
A12: Same word, different sign | B12: Read the direction word together with its topic. Inflasi / kredit / defisit meningkat → HAWKISH. Pertumbuhan melambat / melemah → DOVISH; pertumbuhan kuat / tinggi → leans HAWKISH. Rupiah melemah / terdepresiasi → HAWKISH; Rupiah menguat / stabil → leans DOVISH.
A13: Negation | B13: 'tidak meningkat', 'belum pulih' etc. reverse or qualify the direction word.
A14: Decision paragraphs | B14: A paragraph announcing the rate decision: hike → Hawkish, cut → Dovish, hold → judge the reasoning that follows (a hold 'to anticipate inflation pressure' is Hawkish; a hold 'to support growth' is Dovish; a plain hold is Neutral).
A16: Other columns
A17: Confidence | B17: 1 = unsure / could argue either way · 2 = fairly sure · 3 = clear-cut.
A18: Forward-looking | B18: Y if the paragraph is mainly about the future (diperkirakan, ke depan, akan, prospek, proyeksi); N if it mainly describes what already happened.
A19: Notes | B19: Anything useful: ambiguous wording, mixed signals, a phrase that decided it for you.
A21: Example (not part of the sample)
A22: Text | B22: Inflasi inti diperkirakan meningkat seiring dengan tekanan depresiasi nilai tukar Rupiah dan kenaikan ekspektasi inflasi.
A23: Label / Conf. / Fwd | B23: Hawkish · 3 · Y
A24: Why | B24: Core inflation expected to rise + rupiah depreciation pressure → both point to tighter policy.
A26: Tips | B26: About 220 rows ≈ 2 hours. Take breaks; your progress is shown below. Some items appear twice on purpose (to measure labelling consistency) — just label them again as you see them, without scrolling back.
A28: Progress
A29: Items in sample | B29: =COUNTA(Label!A2:A221) -> 220
A30: Labelled so far | B30: =COUNTA(Label!D2:D221) -> 1
A31: Remaining | B31: =B29-B30 -> 219
A32: % done | B32: =IF(B29=0,0,B30/B29) -> 0.0045454545
A33: Hawkish | B33: =COUNTIF(Label!D2:D221,"Hawkish") -> 1
A34: Neutral | B34: =COUNTIF(Label!D2:D221,"Neutral") -> 0
A35: Dovish | B35: =COUNTIF(Label!D2:D221,"Dovish") -> 0

Sheet Label
A1: Item | B1: Topic | C1: Text (heading + paragraph) | D1: Label | E1: Confidence (1-3) | F1: Forward-looking (Y/N) | G1: Notes | H1: Score
A2: S001 | B2: Global | C2: Ekonomi global diperkirakan tumbuh lebih lambat pada tahun 2016. Pemulihan ekonomi AS masih belum solid, yang diindikasikan oleh melemahnya konsumsi dan beberapa indikator ketenagakerjaan, serta masih rendahnya inflasi. Kondisi ini diperkirakan akan mendorong The Fed untuk tetap secara berhati-hati dalam melakukan penyesuaian suku bunga Fed Fund Rate (FFR). Sejalan dengan itu, pertumbuhan ekonomi Eropa juga masih terbatas dan dibayangi isu Brexit. Sementara itu, perekonomian Jepang masih terus tertekan. Kondisi tersebut mendorong berlanjutnya pelonggaran kebijakan moneter di negara-negara maju, termasuk melalui penerapan suku bunga negatif. Di sisi lain, ekonomi Tiongkok mulai membaik, meskipun masih berisiko, ditopang oleh sektor konstruksi dan real estate. Di pasar komoditas, harga minyak dunia diperkirakan tetap rendah, akibat tingginya pasokan di tengah permintaan yang masih lemah. Namun, harga beberapa komoditas ekspor Indonesia membaik, seperti CPO, timah, dan karet | D2: Hawkish | H2: =IF(D2="Hawkish",1,IF(D2="Dovish",-1,IF(D2="Neutral",0,""))) -> 1
A3: S002 | B3: Other | C3: Penyesuaian ekonomi Indonesia yang terkendali ditopang oleh stabilitas sistem keuangan yang tetap terjaga. Ketahanan industri perbankan tetap solid dengan risiko kredit, likuiditas dan pasar yang cukup terjaga, serta dengan dukungan ketahanan modal yang masih kuat. Pertumbuhan kredit perbankan menurun dari 21,9% pada November 2013 menjadi 21,4% (atau 17,4% dengan menetralkan depresiasi nilai tukar) pada Desember 2013 sejalan dengan permintaan domestik yang melambat dan kenaikan suku bunga. Bank Indonesia akan berkoordinasi dengan OJK untuk mengarahkan pertumbuhan kredit ke depan sejalan dengan moderasi pertumbuhan permintaan domestik. Sementara itu, kinerja pasar saham pada Januari 2014 membaik ditandai dengan kenaikan IHSG. Perkembangan berbeda terlihat pada kinerja pasar obligasi pemerintah yang menurun tercermin pada kenaikan imbal hasil SBN Jakarta, 13 Februari 2014 Departemen Komunikasi Tirta Segara Direktur Eksekutif Laporan lengkap mengenai perkembangan ekonomi makro dan kebijakan moneter yang dibahas pada RDG Februari 2014 dapat dilihat dalam Tinjauan Kebijakan Moneter (TKM) di Website Bank Indonesia | H3: =IF(D3="Hawkish",1,IF(D3="Dovish",-1,IF(D3="Neutral",0,"")))
A4: S003 | B4: Growth | C4: Pertumbuhan ekonomi global semakin tidak merata dan disertai ketidakpastian di pasar keuangan global yang masih tinggi. Ekonomi AS diperkirakan tetap kuat didukung akselerasi konsumsi dan investasi, dan dibarengi tekanan inflasi yang tetap tinggi. Sesuai dengan perkiraan, The Fed menaikkan suku bunga kebijakan Fed Fund Rate (FFR) sebesar 25 bps sebagai bagian dari proses normalisasi kebijakan moneternya. Sementara itu, pertumbuhan ekonomi negara-negara emerging market dan Eropa diperkirakan lebih rendah dari prakiraan. Ekonomi Jepang dan Tiongkok bahkan cenderung menurun. Ketidakmerataan pertumbuhan ekonomi global tersebut tidak terlepas dari ketegangan perdagangan antara AS dengan sejumlah negara lain. Tingginya ketidakpastian di pasar keuangan global juga mendorong para investor menempatkan dananya di aset-aset yang dianggap aman, khususnya di AS. Berbagai perkembangan tersebut pada gilirannya mengakibatkan dolar AS terus menguat yang kemudian mendorong aliran modal keluar dari negara-negara emerging market dan akhirnya menekan banyak mata uang negara berkembang | H4: =IF(D4="Hawkish",1,IF(D4="Dovish",-1,IF(D4="Neutral",0,"")))
A5: S004 | B5: Global | C5: Ketidakpastian pasar keuangan global tetap tinggi di tengah prospek perekonomian dunia yang lebih kuat. Pertumbuhan ekonomi global pada 2024 diprakirakan mencapai 3,2%, lebih tinggi dari prakiraan awal, terutama dengan lebih baiknya pertumbuhan India dan Tiongkok. Ekonomi Amerika Serikat (AS) tumbuh kuat ditopang oleh perbaikan permintaan domestik dan peningkatan ekspor dengan penurunan inflasi AS yang masih berjalan lambat. Kondisi ini mendorong Fed Fund Rate (FFR) diprakirakan baru akan turun pada akhir tahun 2024. Sementara itu, European Central Bank (ECB) telah menurunkan suku bunga kebijakan moneternya lebih cepat sejalan dengan tekanan inflasi yang lebih rendah. Divergensi kebijakan moneter negara maju ini serta masih tingginya ketegangan geopolitik menyebabkan ketidakpastian pasar keuangan global tetap tinggi. Berbagai perkembangan tersebut, dan dengan tingginya yield US treasury , menyebabkan menguatnya nilai tukar dolar AS sehingga meningkatkan tekanan pelemahan nilai tukar berbagai mata uang dunia dan menahan aliran masuk modal asing ke negara berkembang. Ketidakpastian pasar keuangan global yang tinggi ini memerlukan respons kebijakan yang kuat untuk memitigasi dampak negatif dari rambatan ketidakpastian global tersebut terhadap perekonomian di negara-negara berkembang, termasuk Indonesia. Pertumbuhan ekonomi Indonesia tetap kuat di tengah ketidakpastian global, didukung oleh bauran kebijakan Bank Indonesia dan Pemerintah. Konsumsi swasta tumbuh baik seiring dengan terjaganya daya beli dan kuatnya keyakinan konsumen. Investasi meningkat, baik investasi bangunan maupun nonbangunan, sejalan dengan berlanjutnya proyek infrastruktur Pemerintah dan membaiknya investasi swasta. Permintaan domestik triwulan II 2024 yang meningkat antara lain tecermin pada kinerja positif sejumlah indikator konsumsi rumah tangga dan investasi, seperti Indeks Keyakinan Konsumen, Indeks Penjualan Riil, dan Purchasing Managers' Index (PMI) Manufaktur. Selain itu, ekspor barang meningkat didorong kenaikan ekspor pertambangan dan manufaktur ke negara mitra dagang utama, seperti Tiongkok dan India. Ekspor jasa juga membaik ditopang pemulihan perekonomian negara asal wisatawan mancanegara. Secara sektoral, pertumbuhan ekonomi periode triwulan berjalan antara lain didukung oleh pertumbuhan Lapangan Usaha (LU) Industri Pengolahan, LU Konstruksi, dan LU Perdagangan Besar dan Eceran. Dengan berbagai perkembangan tersebut, pertumbuhan ekonomi 2024 diprakirakan berada dalam kisaran 4,7-5,5%. Bank Indonesia akan terus memperkuat sinergi dengan Pemerintah melalui stimulus fiskal dan kebijakan makroprudensial, yang ditempuh secara konsisten dengan menerapkan prinsip kebijakan makroekonomi yang berhati–hati, guna mendukung pertumbuhan ekonomi yang berkelanjutan | H5: =IF(D5="Hawkish",1,IF(D5="Dovish",-1,IF(D5="Neutral",0,"")))
A6: S005 | B6: Inflation | C6: Inflasi IHK Mei 2008 secara bulanan berada jauh di atas pola historisnya dan meningkat menjadi 1,41% dari 0,57% di bulan sebelumnya. Sementara itu, secara tahunan, inflasi Mei 2008 tercatat sebesar 10,38% atau meningkat signifikan dibanding inflasi tahunan bulan sebelumnya (8,96%). Dengan perkembangan tersebut, inflasi year-to-date sampai dengan bulan Mei 2008 telah mencapai 5,47%. Kenaikan harga BBM bersubsidi di akhir bulan memberi dampak yang signifikan pada peningkatan laju inflasi Mei 2008. Aksi menaikkan harga berbagai komoditas menjelang kenaikan harga BBM berkontribusi terhadap tingginya inflasi Mei 2008. Mengingat bahwa dampak kenaikan BBM diperkirakan belum sepenuhnya terefleksi pada inflasi di bulan Mei 2008 maka tekanan inflasi akibat kenaikan harga BBM diperkirakan masih akan berlanjut kembali di bulan-bulan selanjutnya | H6: =IF(D6="Hawkish",1,IF(D6="Dovish",-1,IF(D6="Neutral",0,"")))
A7: S006 | B7: Exchange rate | C7: Nilai tukar rupiah bergerak relatif stabil dan dapat menahan tekanan inflasi yang lebih tinggi akibat meningkatnya harga komoditas internasional. Rata-rata nilai tukar rupiah pada triwulan I-2008 tercatat sebesar Rp9.258,00 per dolar AS. Relatif stabilnya nilai tukar ditopang oleh kinerja Neraca Pembayaran Indonesia yang tetap mencatat surplus seiring dengan tingginya harga komoditas internasional. Dengan perkembangan tersebut, pada akhir triwulan I-2008 posisi cadangan devisa Indonesia meningkat menjadi USD59 miliar atau setara dengan 5,3 bulan impor dan pembayaran utang luar negeri Pemerintah. "Tekanan inflasi ke depan diprakirakan masih cukup tinggi dan didominasi oleh tekanan dari sisi biaya terutama akibat tingginya harga komoditas internasional (imported inflation)", demikian Gubernur Bank Indonesia, Burhanuddin Abdullah. Menyikapi tekanan inflasi lebih lanjut, Bank Indonesia senantiasa mengelola ekspektasi inflasi masyarakat, diantaranya dengan menjaga agar tidak terjadi kelebihan likuiditas di pasar uang. Inflasi bulan Maret 2008 mencapai 0,95% (mtm), sehingga inflasi IHK dalam triwulan pertama tahun 2008 tercatat sebesar 3,41% (qtq) atau 8,17% secara tahunan | H7: =IF(D7="Hawkish",1,IF(D7="Dovish",-1,IF(D7="Neutral",0,"")))
A8: S007 | B8: Inflation | C8: Inflasi tetap rendah dan terjaga dalam kisaran sasaran 2,5±1%. Inflasi Indeks Harga Konsumen (IHK) tercatat rendah di seluruh komponen sehingga mencapai 2,12% (yoy) pada Agustus 2024. Inflasi inti tercatat sebesar 2,02% (yoy), sementara inflasi volatile food (VF) terus menurun menjadi 3,04% (yoy), dari level bulan sebelumnya 3,63% (yoy). Penurunan inflasi VF tercatat di sebagian besar wilayah Indonesia, didukung oleh peningkatan pasokan pangan seiring berlanjutnya musim panen, serta eratnya sinergi pengendalian inflasi TPIP/TPID melalui GNPIP. Ke depan, Bank Indonesia meyakini inflasi IHK tetap terkendali dalam sasarannya. Inflasi inti diprakirakan terjaga seiring ekspektasi inflasi yang terjangkar dalam sasaran, kapasitas perekonomian yang masih besar dan dapat merespons permintaan domestik, imported inflation yang terkendali sejalan dengan kebijakan stabilisasi nilai tukar Rupiah Bank Indonesia, serta dampak positif berkembangnya digitalisasi. Inflasi VF diprakirakan terkendali didukung oleh sinergi pengendalian inflasi Bank Indonesia dan Pemerintah Pusat dan Daerah. Ke depan, Bank Indonesia terus berkomitmen memperkuat efektivitas kebijakan moneter guna menjaga inflasi tahun 2024 dan 2025 terkendali dalam sasaran 2,5±1%, dengan tetap mendukung upaya penguatan pertumbuhan ekonomi | H8: =IF(D8="Hawkish",1,IF(D8="Dovish",-1,IF(D8="Neutral",0,"")))
A9: S008 | B9: Exchange rate | C9: Sementara itu, nilai tukar rupiah sedikit menguat dengan volatilitas yang terjaga, didukung perbaikan rating Indonesia dan ekonomi global. Secara point to point nilai tukar Rupiah menguat 2,08% yakni dari Rp9.263 menjadi Rp9.070 per dolar AS dan secara rata-rata menguat 2,55% dari Rp9.370 pada Juni menjadi Rp9.131 per dolar AS di Juli 2006. Penguatan rupiah tersebut disebabkan oleh membaiknya faktor risiko seperti tercermin pada perbaikan credit rating Indonesia oleh S&P yang didasari oleh membaiknya kinerja kebijakan makro serta terjaganya kondisi fundamental. Kondisi tersebut didukung oleh sentimen eksternal yang positif berupa ekspektasi ditundanya kenaikan suku bunga the Fed pada 8 Agustus 2006. Sementara itu, daya tahan perekonomian domestik terhadap gejolak kenaikan harga minyak dunia semakin menguat seperti ditunjukkan oleh surplus neraca perdagangan migas dan ketahanan fiskal paska kenaikan BBM. Berbagai perkembangan positif tersebut dengan cepat telah direspon oleh pasar keuangan dalam bentuk aliran masuk modal jangka pendek, mencapai USD1,1 miliar selama bulan Juli, dan selanjutnya menambah cadangan devisa Indonesia menjadi USD41,8 miliar pada minggu pertama Agustus 2006. Penurunan BI Rate yang telah dilakukan pada bulan Mei dan Juli 2006 mulai berdampak positif pada suku bunga dana pihak ketiga dan suku bunga kredit meskipun dengan tingkat yang masih terbatas. Kondisi ini telah menyebabkan peningkatan penyaluran kredit yang cukup tinggi pada bulan Juni, yaitu hampir Rp10 triliun sehingga menjadi Rp757,3 triliun pada akhir Juni 2006. Namun demikian, apabila dibandingkan dengan posisi akhir Desember 2005, kenaikan kredit perbankan baru mencapai Rp27,2 triliun atau tumbuh sebesar 3,72%. Dengan perkiraan membaiknya aktivitas ekonomi, kredit diharapkan tumbuh lebih cepat di sisa akhir tahun 2006. Optimisme ini, selain didukung oleh menurunnya suku bunga, juga didukung oleh menurunnya risiko kredit yang tercermin dari penurunan NPL dari 8,8% menjadi 8,7%. Walaupun pembiayaan perbankan lebih rendah dari perkiraan, namun demikian, sumber pembiayaan non bank (saham, obligasi dan lembaga keuangan non bank) menunjukkan peningkatan yang menggembirakan. Selama semester I-2006 nilai emisi saham meningkat sebesar 7,4 triliun dan emisi obligasi meningkat Rp. 4,9 triliun. Dari eksternal, pembiayaan dari luar negeri kepada sektor swasta juga mengalami peningkatan sebesar USD705 juta pada bulan Juni 2006. Ke depan, kegiatan ekonomi diharapkan meningkat pada Semester II yang didukung oleh semakin membaiknya kondisi ekonomi makro. Sejauh ini peningkatan tersebut belum akan berdampak pada harga-harga sehingga inflasi diperkirakan masih sesuai dengan sasarannya di tahun 2006 dan 2007. Faktor risiko eksternal berupa berlanjutnya kenaikan harga minyak dan pengetatan kebijakan moneter global akan senantiasa menjadi perhatian Bank Indonesia. Dengan pertimbangan utama pada semakin meningkatnya stabilitas makro dan keyakinan pasar, serta berkurangnya risiko dari sisi eksternal, terutama lebih jelasnya arah suku bunga The Fed, Rapat Dewan Gubernur hari ini memutuskan untuk menurunkan BI rate sebesar 50 bps dari 12,25% menjadi 11,75%. Penurunan suku bunga ini diharapkan juga dapat mendorong kembali optimisme di sektor konsumen dan sektor usaha sehingga pada gilirannya dapat mendorong bergeraknya sektor riil tanpa menimbulkan tekanan inflasi yang berlebihan | H9: =IF(D9="Hawkish",1,IF(D9="Dovish",-1,IF(D9="Neutral",0,"")))
A10: S009 | B10: Exchange rate | C10: Nilai tukar Rupiah tetap terkendali dengan mekanisme pasar yang berjalan baik, meskipun mulai Juli 2020 melemah dipengaruhi ketidakpastian pasar keuangan global. Pada Juli 2020, Rupiah mencatat depresiasi 2,36% secara point to point atau 2,92% secara rerata dibandingkan dengan level Juni 2020, dipicu kekhawatiran terhadap terjadinya gelombang kedua pandemi COVID-19, prospek pemulihan ekonomi global, dan peningkatan ketidakpastian pasar keuangan global akibat kenaikan tensi geopolitik AS–Tiongkok. Kekhawatiran yang sama berlanjut sehingga Rupiah pada Agustus 2020 kembali mendapat tekanan yang per 18 Agustus 2020 mencatat depresiasi 1,65% secara point to point atau 1,04% secara rerata dibandingkan dengan level Juli 2020. Dibandingkan dengan level akhir 2019, Rupiah terdepresiasi 6,48% (ytd). Ke depan, Bank Indonesia memandang nilai tukar Rupiah masih berpotensi menguat seiring levelnya yang secara fundamental masih undervalued didukung inflasi yang rendah dan terkendali, defisit transaksi berjalan yang rendah, daya tarik aset keuangan domestik yang tinggi, dan premi risiko Indonesia yang menurun. Selain itu, prospek pemulihan ekonomi yang menguat pada semester II 2020 juga dapat mendukung prospek penguatan nilai tukar Rupiah. Untuk mendukung efektivitas kebijakan nilai tukar, Bank Indonesia terus menjaga ketersediaan likuiditas baik di pasar uang maupun pasar valas dan memastikan bekerjanya mekanisme pasar | H10: =IF(D10="Hawkish",1,IF(D10="Dovish",-1,IF(D10="Neutral",0,"")))
A11: S010 | B11: Decision | C11: Rapat Dewan Gubernur (RDG) Bank Indonesia pada hari ini, 6 Maret 2008, memutuskan untuk mempertahankan BI Rate pada tingkat 8%. Keputusan tersebut diambil setelah mempertimbangkan prospek dan tantangan pencapaian sasaran inflasi tahun 2008 dan 2009 yang ditetapkan oleh Pemerintah serta asesmen mendalam terhadap kondisi makroekonomi Indonesia | H11: =IF(D11="Hawkish",1,IF(D11="Dovish",-1,IF(D11="Neutral",0,"")))
A12: S011 | B12: Exchange rate | C12: Kinerja NPI yang menurun memberikan tekanan kepada nilai tukar Rupiah pada 2013 dan disertai volatilitas yang meningkat. Rupiah secara point-to-point melemah 20,8%(yoy) selama tahun 2013 ke level Rp12.170 per dolar AS atau secara rata-rata melemah 10,4% (yoy) ke level Rp10.445 per dolar AS. Tekanan terhadap rupiah terutama cukup kuat terjadi sejak akhir Mei 2013 hingga Agustus 2013, sejalan dengan meningkatnya aliran modal keluar dipicu sentimen terhadap rencana pengurangan stimulus moneter oleh The Fed, di tengah kenaikan inflasi domestik pasca kenaikan harga BBM bersubsidi dan persepsi terhadap prospek transaksi berjalan di dalam negeri. Pengaruh global yang cukup kuat tersebut tergambar pada pergerakan rupiah yang searah dengan pelemahan mata uang di negara kawasan. Bank Indonesia terus menjaga stabilitas nilai tukar rupiah sesuai dengan nilai fundamentalnya sehingga dapat mendukung penyesuaian ekonomi secara terkendali. Perbaikan kinerja NPI dengan defisit transaksi berjalan yang menurun diperkirakan akan mendukung pergerakan nilai tukar Rupiah yang lebih stabil dan cenderung menguat ke depan | H12: =IF(D12="Hawkish",1,IF(D12="Dovish",-1,IF(D12="Neutral",0,"")))
A13: S012 | B13: Monetary policy | C13: Keputusan tersebut sejalan dengan ruang pelonggaran kebijakan moneter yang semakin terbuka dengan semakin terjaganya stabilitas makroekonomi, khususnya penurunan tekanan inflasi di 2016, serta meredanya ketidakpastian di pasar keuangan global. Kebijakan penurunan BI Rate dan GWM Primer dalam Rupiah tersebut diharapkan dapat memperkuat upaya mendorong pertumbuhan ekonomi yang sedang berlangsung. Bank Indonesia juga akan terus memperkuat koordinasi dengan Pemerintah untuk memastikan pengendalian inflasi, penguatan stimulus pertumbuhan, dan reformasi struktural berjalan dengan baik, sehingga mampu menopang pertumbuhan ekonomi yang berkelanjutan ke depan dengan tetap menjaga stabilitas makroekonomi | H13: =IF(D13="Hawkish",1,IF(D13="Dovish",-1,IF(D13="Neutral",0,"")))
A14: S013 | B14: Monetary policy | C14: Bank Indonesia terus memperkuat kebijakan moneter untuk mendorong pertumbuhan ekonomi dengan tetap menjaga stabilitas perekonomian. Kebijakan moneter ditempuh melalui penurunan suku bunga BI-Rate, stabilisasi nilai tukar Rupiah, dan ekspansi likuiditas moneter. BI-Rate telah turun sebesar 150 bps, yaitu 25 bps pada September 2024 dan 125 bps selama tahun 2025 menjadi 4,75% hingga Oktober 2025, yang merupakan level terendah sejak tahun 2022. Kebijakan stabilisasi nilai tukar Rupiah terus diperkuat dengan intervensi di pasar off-shore melalui NDF dan intervensi di pasar domestik melalui pasar spot , DNDF, serta pembelian SBN di pasar sekunder. Sejalan dengan itu, Bank Indonesia menetapkan suku bunga instrumen moneter valas yang kompetitif untuk menjaga daya tarik penempatan dana di Indonesia yang dapat mendukung stabilitas nilai tukar Rupiah. Ekspansi likuiditas Rupiah juga ditempuh Bank Indonesia melalui penurunan posisi instrumen moneter SRBI dari Rp916,97 triliun pada awal tahun 2025 menjadi Rp699,30 triliun pada 17 November 2025. Bank Indonesia membeli SBN sebagai bentuk sinergi erat antara kebijakan moneter dan kebijakan fiskal, yang hingga 18 November 2025 mencapai Rp289,91 triliun, termasuk pembelian di pasar sekunder dan program debt switching dengan Pemerintah sebesar Rp212,60 triliun. Pembelian SBN di pasar sekunder dilakukan sesuai mekanisme pasar, terukur, transparan, dan konsisten dengan program moneter dalam menjaga stabilitas perekonomian sehingga dapat terus menjaga kredibilitas kebijakan moneter | H14: =IF(D14="Hawkish",1,IF(D14="Dovish",-1,IF(D14="Neutral",0,"")))
... A221: S220 | B221: Decision | C221: Rapat Dewan Gubernur (RDG) Bank Indonesia pada 5 Oktober 2010 memutuskan untuk mempertahankan BI Rate pada tingkat 6,50%. Keputusan tersebut didasarkan atas hasil evaluasi menyeluruh terhadap kinerja dan prospek perekonomian yang secara umum menunjukkan peningkatan. Bank Indonesia mencermati adanya tekanan inflasi ditengah masih derasnya arus modal asing yang masuk dan kondisi ekses likuiditas yang masih cukup besar. Untuk saat ini, Dewan Gubernur memandang pengelolaan likuiditas perekonomian merupakan hal yang lebih penting. Sementara itu, level BI Rate saat ini masih konsisten dengan pencapaian sasaran inflasi dan tetap kondusif untuk menjaga stabilitas keuangan dan mendorong intermediasi perbankan, sehingga sisi suppl y dapat merespon akselerasi di sisi permintaan secara memadai | H221: =IF(D221="Hawkish",1,IF(D221="Dovish",-1,IF(D221="Neutral",0,"")))

Sheet Key
A1: item | B1: repeat_of | C1: code | D1: lang | E1: date | F1: era | G1: section_order | H1: topic | I1: heading_key | J1: n_words | K1: direction | L1: bps | M1: rate_level
A2: S001 | C2: 183816 | D2: id | E2: 2016-05-19 | F2: 2012-16 | G2: 2 | H2: global | I2: ekonomi global diperkirakan tumbuh lebih lambat | J2: 122 | K2: hold | L2: 0 | M2: 6.75
A3: S002 | C3: 160813 | D3: id | E3: 2014-02-13 | F3: 2012-16 | G3: 7 | H3: other | I3: penyesuaian ekonomi indonesia yang terkendali ditopang | J3: 136 | K3: hold | L3: 0 | M3: 7.5
A4: S003 | C4: 207318 | D4: id | E4: 2018-09-27 | F4: 2017-20 | G4: 3 | H4: growth | I4: pertumbuhan ekonomi global semakin tidak merata | J4: 125 | K4: hike | L4: 25 | M4: 5.75
A5: S004 | C5: 2612524 | D5: id | E5: 2024-06-20 | F5: 2021-26 | G5: 2 | H5: global | I5: ketidakpastian pasar keuangan global tetap tinggi | J5: 339 | K5: hold | L5: 0 | M5: 6.25
A6: S005 | C6: 100608-1 | D6: id | E6: 2008-06-05 | F6: 2005-11 | G6: 6 | H6: inflation | I6: inflasi ihk mei 2008 secara bulanan | J6: 94 | K6: hike | L6: 25 | M6: 8.5
A7: S006 | C7: 101908 | D7: id | E7: 2008-04-03 | F7: 2005-11 | G7: 3 | H7: exchange_rate | I7: nilai tukar rupiah bergerak relatif stabil | J7: 135 | K7: hold | L7: 0 | M7: 8
A8: S007 | C8: 2620124 | D8: id | E8: 2024-09-18 | F8: 2021-26 | G8: 5 | H8: inflation | I8: inflasi tetap rendah dan terjaga dalam | J8: 159 | K8: cut | L8: 25 | M8: 6
A9: S008 | C9: SP8422006 | D9: id | E9: 2006-08-08 | F9: 2005-11 | G9: 4 | H9: exchange_rate | I9: sementara itu nilai tukar rupiah sedikit | J9: 450 | K9: cut | L9: 50 | M9: 11.75
A10: S009 | C10: 226420 | D10: id | E10: 2020-08-19 | F10: 2017-20 | G10: 5 | H10: exchange_rate | I10: nilai tukar rupiah tetap terkendali dengan | J10: 170 | K10: hold | L10: 0 | M10: 4
A11: S010 | C11: 101208 | D11: id | E11: 2008-03-06 | F11: 2005-11 | G11: 1 | H11: decision | I11: rapat dewan gubernur rdg bank indonesia | J11: 26 | K11: hold | L11: 0 | M11: 8
A12: S011 | C12: 160214 | D12: id | E12: 2014-01-09 | F12: 2012-16 | G12: 5 | H12: exchange_rate | I12: kinerja npi yang menurun memberikan tekanan | J12: 137 | K12: hold | L12: 0 | M12: 7.5
A13: S012 | C13: 181416 | D13: id | E13: 2016-02-18 | F13: 2012-16 | G13: 2 | H13: monetary_policy | I13: keputusan tersebut sejalan dengan ruang pelonggaran | J13: 56 | K13: cut | L13: 25 | M13: 7
... A147: S146 | C147: 102308 | D147: id | E147: 2008-05-06 | F147: 2005-11 | G147: 3 | H147: inflation | I147: inflasi bulan april 2008 tercatat sebesar | J147: 41 | K147: hike | L147: 25 | M147: 8.25
A148: S147 | B148: S017 | C148: 123910 | D148: id | E148: 2010-08-04 | F148: 2005-11 | G148: 6 | H148: inflation | I148: bank indonesia akan terus memperkuat langkah | J148: 40 | K148: hold | L148: 0 | M148: 6.5
A149: S148 | C149: 122310 | D149: id | E149: 2010-05-05 | F149: 2005-11 | G149: 4 | H149: bop | I149: perbaikan kinerja sektor eksternal tersebut berdampak | J149: 88 | K149: hold | L149: 0 | M149: 6.5
A150: S149 | C150: 179515 | D150: id | E150: 2015-12-17 | F150: 2012-16 | G150: 2 | H150: growth | I150: tantangan yang dihadapi ekonomi indonesia selama | J150: 102 | K150: hold | L150: 0 | M150: 7.5
A151: S150 | C151: 86106 | D151: id | E151: 2006-12-07 | F151: 2005-11 | G151: 3 | H151: exchange_rate | I151: nilai tukar rupiah menguat dengan volatilitas | J151: 53 | K151: cut | L151: 50 | M151: 9.75
A152: S151 | C152: 14312 | D152: id | E152: 2012-02-09 | F152: 2012-16 | G152: 7 | H152: credit | I152: stabilitas sistem keuangan tetap terjaga yang | J152: 75 | K152: cut | L152: 25 | M152: 5.75
A153: S152 | C153: 209618 | D153: id | E153: 2018-12-20 | F153: 2017-20 | G153: 7 | H153: credit | I153: stabilitas sistem keuangan tetap terjaga disertai | J153: 189 | K153: hold | L153: 0 | M153: 6
A154: S153 | C154: 212519 | D154: id | E154: 2019-04-25 | F154: 2017-20 | G154: 3 | H154: growth | I154: pertumbuhan ekonomi triwulan i 2019 diprakirakan | J154: 105 | K154: hold | L154: 0 | M154: 6
A155: S154 | B155: S005 | C155: 100608-1 | D155: id | E155: 2008-06-05 | F155: 2005-11 | G155: 6 | H155: inflation | I155: inflasi ihk mei 2008 secara bulanan | J155: 94 | K155: hike | L155: 25 | M155: 8.5
A156: S155 | B156: S028 | C156: 2814226 | D156: id | E156: 2026-07-22 | F156: 2021-26 | G156: 1 | H156: decision | I156: rapat dewan gubernur rdg bank indonesia | J156: 275 | K156: hold | L156: 0 | M156: 5.75
A157: S156 | C157: 229520 | D157: id | E157: 2020-12-17 | F157: 2017-20 | G157: 6 | H157: monetary_policy | I157: sejalan dengan kebijakan moneter dan makroprudensial | J157: 176 | K157: hold | L157: 0 | M157: 3.75
A158: S157 | C158: 227120 | D158: id | E158: 2020-09-17 | F158: 2017-20 | G158: 5 | H158: exchange_rate | I158: dengan langkah langkah stabilisasi bank indonesia | J158: 114 | K158: hold | L158: 0 | M158: 4
A159: S158 | B159: S046 | C159: 288426 | D159: id | E159: 2026-04-22 | F159: 2021-26 | G159: 3 | H159: growth | I159: pertumbuhan ekonomi indonesia perlu terus | J159: 184 | K159: hold | L159: 0 | M159: 4.75
A160: S159 | C160: 227520 | D160: id | E160: 2020-10-13 | F160: 2017-20 | G160: 6 | H160: inflation | I160: inflasi tetap rendah sejalan permintaan yang | J160: 166 | K160: hold | L160: 0 | M160: 4
A161: S160 | C161: 221320 | D161: id | E161: 2020-02-20 | F161: 2017-20 | G161: 2 | H161: global | I161: proses pemulihan ekonomi global tertahan setelah | J161: 151 | K161: cut | L161: 25 | M161: 4.75
A162: S161 | B162: S010 | C162: 101208 | D162: id | E162: 2008-03-06 | F162: 2005-11 | G162: 1 | H162: decision | I162: rapat dewan gubernur rdg bank indonesia | J162: 26 | K162: hold | L162: 0 | M162: 8
A163: S162 | C163: 208718 | D163: id | E163: 2018-11-15 | F163: 2017-20 | G163: 1 | H163: decision | I163: rapat dewan gubernur rdg bank indonesia | J163: 188 | K163: hike | L163: 25 | M163: 6
A164: S163 | B164: S070 | C164: 223920 | D164: id | E164: 2020-05-19 | F164: 2017-20 | G164: 8 | H164: money_supply | I164: kondisi likuiditas perbankan tetap memadai dan | J164: 194 | K164: hold | L164: 0 | M164: 4.5
A165: S164 | C165: 140512 | D165: id | E165: 2012-03-08 | F165: 2012-16 | G165: 6 | H165: credit | I165: stabilitas sistem perbankan tetap terjaga dan | J165: 84 | K165: hold | L165: 0 | M165: 5.75
A166: S165 | B166: S127 | C166: 124210 | D166: id | E166: 2010-09-03 | F166: 2005-11 | G166: 5 | H166: credit | I166: di bidang stabilitas sistem keuangan dewan | J166: 66 | K166: hold | L166: 0 | M166: 6.5
A167: S166 | C167: 104508 | D167: id | E167: 2008-10-07 | F167: 2005-11 | G167: 2 | H167: global | I167: keputusan ini diambil setelah mencermati dan | J167: 79 | K167: hike | L167: 25 | M167: 9.5
A168: S167 | C168: 101908 | D168: id | E168: 2008-04-03 | F168: 2005-11 | G168: 5 | H168: global | I168: ke depan bank indonesia memandang bahwa | J168: 98 | K168: hold | L168: 0 | M168: 8
A169: S168 | B169: S049 | C169: 2625424 | D169: id | E169: 2024-11-20 | F169: 2021-26 | G169: 5 | H169: exchange_rate | I169: kebijakan nilai tukar bank indonesia terus | J169: 154 | K169: hold | L169: 0 | M169: 6
A170: S169 | C170: 2715325 | D170: id | E170: 2025-07-16 | F170: 2021-26 | G170: 3 | H170: growth | I170: pertumbuhan ekonomi indonesia perlu terus didorong | J170: 232 | K170: cut | L170: 25 | M170: 5.25
A171: S170 | B171: S120 | C171: 2620124 | D171: id | E171: 2024-09-18 | F171: 2021-26 | G171: 3 | H171: growth | I171: pertumbuhan ekonomi indonesia tetap baik dan | J171: 176 | K171: cut | L171: 25 | M171: 6
A172: S171 | C172: 208718 | D172: id | E172: 2018-11-15 | F172: 2017-20 | G172: 2 | H172: monetary_policy | I172: untuk mendorong lebih lanjut pendalaman pasar | J172: 69 | K172: hike | L172: 25 | M172: 6
A173: S172 | C173: 093207 | D173: id | E173: 2007-09-06 | F173: 2005-11 | G173: 5 | H173: bop | I173: sementara itu kinerja neraca pembayaran indonesia | J173: 112 | K173: hold | L173: 0 | M173: 8.25
...
